Workbook

Sheet Data
A1: ReportForNavId_1 | B1: StartDate | C1: FinancialYear | D1: Asat | E1: Name | F1: Cashinhand | G1: Cashatbank | H1: CashCashEquivalent | I1: PrepaymentsSundryReceivables | J1: FinancialInvestments | K1: GovernmentSecurities | L1: Placement | M1: CommercialPapers | N1: CollectiveInvestment | O1: Derivatives | P1: EquityInvestments | Q1: Investmentincompanies | R1: GrossLoanPortfolio | S1: PropertyEquipment | T1: AllowanceforLoanLoss | U1: Nonwithdrawabledeposits | V1: TaxPayable | W1: DeferredTaxLiability | X1: RetirementBenefitsLiability | Y1: OtherLiabilities | Z1: ExternalBorrowings | AA1: TotalLiabilities | AB1: ShareCapital | AC1: StatutoryReserve | AD1: OtherReserves | AE1: RevaluationReserves | AF1: ProposedDividends | AG1: AdjustmenttoEquity | AH1: PrioryarRetainedEarnings | AI1: CurrentYearSurplus | AJ1: TaxRecoverable | AK1: DeferredTaxAssets | AL1: RetirementBenefitAssets | AM1: OtherAssets | AN1: IntangibleAssets | AO1: PrepaidLeaseentals | AP1: InvestmentProperties | AQ1: DividendPayable | AR1: NetLoanPortfolio | AS1: AccountsReceivables | AT1: PropertyEquipmentOtheassets | AU1: AccountsPayableOtherLiabilities | AV1: CapitalGrants | AW1: EQUITY | AX1: RetainedEarnings | AY1: OtherEquityAccounts | AZ1: TotalEquity | BA1: TotalLiabilitiesandEquity | BB1: TotalLiabilitiesNew | BC1: TotalAssets | BD1: ShortTermDeposits | BE1: WithdrawableFOSASavings

Sheet Statement of Fnancial Position
B1: FORM 2G
B2: STATEMENT OF FINANCIAL POSITION
B3: NAME OF SACCO SOCIETY | C3: =Data[Name] -> 0
B4: SACCO SOCIETY CS NUMBER
B5: FINANCIAL YEAR | C5: =Data[FinancialYear] -> 0
B6: START DATE: | C6: =Data[StartDate] -> 0
B7: END DATE: | C7: =Data[Asat] -> 0
C8: Year to Date
C9: AMOUNT(KSHS)
A10: Ref No | B10: ASSETS
A11: 1 | B11: Cash & Cash Equivalent | C11: =SUM(C12:C13) -> 0
A12: 1.1 | B12: Cash in hand(both local and foreign notes and coins) | C12: =SUM(Data!F2) -> 0
A13: 1.2 | B13: Cash at bank:(placement with financial institutions) | C13: =SUM(Data!G2) -> 0
A15: 2 | B15: Prepayments & Sundry Receivables | C15: =SUM(Data!I2) -> 0
A17: 3 | B17: Financial Investments | C17: =SUM(C18:C24) -> 0
A18: 3.1 | B18: Government Securities - Treasury Bills/bonds, | C18: =SUM(Data!K2) -> 0
A19: 3.2 | B19: Placement in Commercial Banks, Saccos and similar financial Institutions | C19: =SUM(Data!L2) -> 0
A20: 3.3 | B20: Commercial Papers, notes and Bonds | C20: =SUM(Data!M2) -> 0
A21: 3.4 | B21: Collective Investment Schemes | C21: =SUM(Data!N2) -> 0
A22: 3.5 | B22: Derivatives | C22: =SUM(Data!O2) -> 0
A23: 3.6 | B23: Equity Investments in subsidiaries and related companies | C23: =SUM(Data!P2) -> 0
A24: 3.7 | B24: Investment in companies-shares/stocks | C24: =SUM(Data!Q2) -> 0
A26: 4 | B26: Net Loan Portfolio | C26: =C27-C28 -> 0
A27: 4.1 | B27: Gross Loan Portfolio | C27: =SUM(Data!R2) -> 0
A28: 4.2 | B28: Allowance for Loan Loss | C28: =SUM(Data!T2) -> 0
A30: 5 | B30: Accounts Receivables | C30: =SUM(C31:C33) -> 0
A31: 5.1 | B31: Tax Recoverable | C31: =SUM(Data!AJ2) -> 0
A32: 5.2 | B32: Deferred Tax Assets | C32: =SUM(Data!AK2) -> 0
A33: 5.3 | B33: Retirement Benefit Assets | C33: =SUM(Data!AL2) -> 0
A35: 6 | B35: Property & Equipment & Other assets | C35: =SUM(C36:C40) -> 0
A36: 6.1 | B36: Investment Properties | C36: =SUM(Data!AP2) -> 0
A37: 6.2 | B37: Property & Equipment | C37: =SUM(Data!S2) -> 0
A38: 6.3 | B38: Prepaid Lease rentals | C38: =SUM(Data!AO2) -> 0
A39: 6.4 | B39: Intangible Assets | C39: =SUM(Data!AN2) -> 0
A40: 6.5 | B40: Other Assets | C40: =SUM(Data!AM2) -> 0
B42: Total Assets | C42: =SUM(C11,C15,C17,C26,C30,C35) -> 0
B45: LIABILITIES
A46: 7 | B46: Savings Deposits - Withdrawable deposits - FOSA) | C46: =SUM(Data!BE2) -> 0
A47: 8 | B47: Short Term Deposits (e.g Fixed deposits, special savings) | C47: =SUM(Data!BD2) -> 0
A48: 9 | B48: Non withdrawable deposits (BOSA member deposits) | C48: =SUM(Data!U2) -> 0
...
